<?xml version="1.0" encoding="utf-8"?>
<!-- This URDF was automatically created by SolidWorks to URDF Exporter! Originally created by Stephen Brawner (brawner@gmail.com) 
     Commit Version: 1.5.1-0-g916b5db  Build Version: 1.5.7152.31018
     For more information, please see http://wiki.ros.org/sw_urdf_exporter -->
<robot name="omove">
  <link name="base_footprint" />
  <joint name="base_joint" type="fixed">
    <parent link="base_footprint" />
    <child link="base_link" />
    <origin rpy="0 0 0" xyz="0 0 0" />
  </joint>

  <link
    name="base_link">
    <inertial>
      <origin
        xyz="0.0021031 0.00024334 0.023555"
        rpy="0 0 0" />
      <mass
        value="8.9957" />
      <inertia
        ixx="0.0064797"
        ixy="2.6634E-06"
        ixz="3.4878E-07"
        iyy="0.03319"
        iyz="-4.9172E-07"
        izz="0.038203" />
    </inertial>
    <visual>
      <origin
        xyz="0 0 0"
        rpy="0 0 0" />
      <geometry>
        <mesh
          filename="package://cartographer_ros/urdf/meshes/base_link.STL" />
      </geometry>
      <material
        name="">
        <color
          rgba="0.75294 0.75294 0.75294 1" />
      </material>
    </visual>
    <collision>
      <origin
        xyz="0 0 0"
        rpy="0 0 0" />
      <geometry>
        <mesh
          filename="package://cartographer_ros/urdf/meshes/base_link.STL" />
      </geometry>
    </collision>
  </link>
  <link
    name="wheel_link_LF">
    <inertial>
      <origin
        xyz="1.0213E-06 -0.0017375 1.8674E-07"
        rpy="0 0 0" />
      <mass
        value="0.28002" />
      <inertia
        ixx="0.00017252"
        ixy="-5.7605E-12"
        ixz="-3.1448E-09"
        iyy="0.00031502"
        iyz="-1.1987E-10"
        izz="0.00017252" />
    </inertial>
    <visual>
      <origin
        xyz="0 0 0"
        rpy="0 0 0" />
      <geometry>
        <mesh
          filename="package://cartographer_ros/urdf/meshes/wheel_link_LF.STL" />
      </geometry>
      <material
        name="">
        <color
          rgba="0.75294 0.75294 0.75294 1" />
      </material>
    </visual>
    <collision>
      <origin
        xyz="0 0 0"
        rpy="0 0 0" />
      <geometry>
        <mesh
          filename="package://cartographer_ros/urdf/meshes/wheel_link_LF.STL" />
      </geometry>
    </collision>
  </link>
  <joint
    name="wheel_joint_LF"
    type="continuous">
    <origin
      xyz="0.175 0.15542 0.012"
      rpy="0 0 0" />
    <parent
      link="base_link" />
    <child
      link="wheel_link_LF" />
    <axis
      xyz="0 1 0" />
  </joint>
  <link
    name="wheel_link_RF">
    <inertial>
      <origin
        xyz="6.7443E-07 0.0017375 -8.1952E-07"
        rpy="0 0 0" />
      <mass
        value="0.28002" />
      <inertia
        ixx="0.00017252"
        ixy="-6.0255E-11"
        ixz="-2.6815E-09"
        iyy="0.00031502"
        iyz="-6.2048E-11"
        izz="0.00017252" />
    </inertial>
    <visual>
      <origin
        xyz="0 0 0"
        rpy="0 0 0" />
      <geometry>
        <mesh
          filename="package://cartographer_ros/urdf/meshes/wheel_link_RF.STL" />
      </geometry>
      <material
        name="">
        <color
          rgba="0.75294 0.75294 0.75294 1" />
      </material>
    </visual>
    <collision>
      <origin
        xyz="0 0 0"
        rpy="0 0 0" />
      <geometry>
        <mesh
          filename="package://cartographer_ros/urdf/meshes/wheel_link_RF.STL" />
      </geometry>
    </collision>
  </link>
  <joint
    name="wheel_joint_RF"
    type="continuous">
    <origin
      xyz="0.175 -0.15542 0.012"
      rpy="0 0 0" />
    <parent
      link="base_link" />
    <child
      link="wheel_link_RF" />
    <axis
      xyz="0 -1 0" />
  </joint>
  <link
    name="wheel_link_LB">
    <inertial>
      <origin
        xyz="-5.2916E-07 -0.0017375 -9.5409E-07"
        rpy="0 0 0" />
      <mass
        value="0.28002" />
      <inertia
        ixx="0.00017252"
        ixy="-5.2924E-11"
        ixz="3.3134E-09"
        iyy="0.00031502"
        iyz="3.5498E-11"
        izz="0.00017252" />
    </inertial>
    <visual>
      <origin
        xyz="0 0 0"
        rpy="0 0 0" />
      <geometry>
        <mesh
          filename="package://cartographer_ros/urdf/meshes/wheel_link_LB.STL" />
      </geometry>
      <material
        name="">
        <color
          rgba="0.75294 0.75294 0.75294 1" />
      </material>
    </visual>
    <collision>
      <origin
        xyz="0 0 0"
        rpy="0 0 0" />
      <geometry>
        <mesh
          filename="package://cartographer_ros/urdf/meshes/wheel_link_LB.STL" />
      </geometry>
    </collision>
  </link>
  <joint
    name="wheel_joint_LB"
    type="continuous">
    <origin
      xyz="-0.175 0.15542 0.012"
      rpy="0 0 0" />
    <parent
      link="base_link" />
    <child
      link="wheel_link_LB" />
    <axis
      xyz="0 1 0" />
  </joint>
  <link
    name="wheel_link_RB">
    <inertial>
      <origin
        xyz="8.5335E-07 0.0017375 -5.9736E-07"
        rpy="0 0 0" />
      <mass
        value="0.28002" />
      <inertia
        ixx="0.00017253"
        ixy="-3.3926E-11"
        ixz="4.3758E-11"
        iyy="0.00031502"
        iyz="-1.2838E-10"
        izz="0.00017252" />
    </inertial>
    <visual>
      <origin
        xyz="0 0 0"
        rpy="0 0 0" />
      <geometry>
        <mesh
          filename="package://cartographer_ros/urdf/meshes/wheel_link_RB.STL" />
      </geometry>
      <material
        name="">
        <color
          rgba="0.75294 0.75294 0.75294 1" />
      </material>
    </visual>
    <collision>
      <origin
        xyz="0 0 0"
        rpy="0 0 0" />
      <geometry>
        <mesh
          filename="package://cartographer_ros/urdf/meshes/wheel_link_RB.STL" />
      </geometry>
    </collision>
  </link>
  <joint
    name="wheel_joint_RB"
    type="continuous">
    <origin
      xyz="-0.175 -0.15542 0.012"
      rpy="0 0 0" />
    <parent
      link="base_link" />
    <child
      link="wheel_link_RB" />
    <axis
      xyz="0 -1 0" />
  </joint>
  <link
    name="laser_link">
    <inertial>
      <origin
        xyz="-0.014867 0.0024602 -0.01678"
        rpy="0 0 0" />
      <mass
        value="0.063786" />
      <inertia
        ixx="1.7112E-05"
        ixy="2.8944E-09"
        ixz="4.4587E-07"
        iyy="2.0808E-05"
        iyz="-1.5142E-08"
        izz="3.568E-05" />
    </inertial>
    <visual>
      <origin
        xyz="0 0 0"
        rpy="0 0 0" />
      <geometry>
        <mesh
          filename="package://cartographer_ros/urdf/meshes/laser_link.STL" />
      </geometry>
      <material
        name="">
        <color
          rgba="0.75294 0.75294 0.75294 1" />
      </material>
    </visual>
    <collision>
      <origin
        xyz="0 0 0"
        rpy="0 0 0" />
      <geometry>
        <mesh
          filename="package://cartographer_ros/urdf/meshes/laser_link.STL" />
      </geometry>
    </collision>
  </link>
  <joint
    name="laser_joint"
    type="fixed">
    <origin
      xyz="0.032502 -0.0017362 0.14767"
      rpy="0 0 0" />
    <parent
      link="base_link" />
    <child
      link="laser_link" />
    <axis
      xyz="0 0 0" />
  </joint>
  <link
    name="depth_link">
    <inertial>
      <origin
        xyz="-0.0042269 0.0032377 -0.0020974"
        rpy="0 0 0" />
      <mass
        value="0.04821" />
      <inertia
        ixx="2.7396E-05"
        ixy="-4.2598E-07"
        ixz="7.55E-09"
        iyy="3.3506E-06"
        iyz="2.1149E-09"
        izz="2.6657E-05" />
    </inertial>
    <visual>
      <origin
        xyz="0 0 0"
        rpy="0 0 0" />
      <geometry>
        <mesh
          filename="package://cartographer_ros/urdf/meshes/depth_link.STL" />
      </geometry>
      <material
        name="">
        <color
          rgba="0.77647 0.75686 0.73725 1" />
      </material>
    </visual>
    <collision>
      <origin
        xyz="0 0 0"
        rpy="0 0 0" />
      <geometry>
        <mesh
          filename="package://cartographer_ros/urdf/meshes/depth_link.STL" />
      </geometry>
    </collision>
  </link>
  <joint
    name="depth_joint"
    type="fixed">
    <origin
      xyz="0.18068 -0.0032372 0.13055"
      rpy="0 0 0" />
    <parent
      link="base_link" />
    <child
      link="depth_link" />
    <axis
      xyz="0 0 0" />
  </joint>
  <link
    name="imu_link">
    <inertial>
      <origin
        xyz="0.026867 -7.317E-05 -0.0012683"
        rpy="0 0 0" />
      <mass
        value="0.013291" />
      <inertia
        ixx="3.4375E-06"
        ixy="3.7116E-08"
        ixz="-6.3445E-11"
        iyy="5.1704E-06"
        iyz="-3.602E-12"
        izz="8.5546E-06" />
    </inertial>
    <visual>
      <origin
        xyz="0 0 0"
        rpy="0 0 0" />
      <geometry>
        <mesh
          filename="package://cartographer_ros/urdf/meshes/imu_link.STL" />
      </geometry>
      <material
        name="">
        <color
          rgba="0.75294 0.75294 0.75294 1" />
      </material>
    </visual>
    <collision>
      <origin
        xyz="0 0 0"
        rpy="0 0 0" />
      <geometry>
        <mesh
          filename="package://cartographer_ros/urdf/meshes/imu_link.STL" />
      </geometry>
    </collision>
  </link>
  <joint
    name="imu_joint"
    type="fixed">
    <origin
      xyz="-0.011302 3.3608E-05 0.04817"
      rpy="0 0 0" />
    <parent
      link="base_link" />
    <child
      link="imu_link" />
    <axis
      xyz="0 0 0" />
  </joint>
</robot>
